<?xml version="1.0" ?>
<!-- =================================================================================== -->
<!-- |    This document was autogenerated by xacro from /home/developer/ros_ws/src/reactor_arm/reactor_description/urdf/reactor_description.xacro | -->
<!-- |    EDITING THIS FILE BY HAND IS NOT RECOMMENDED                                 | -->
<!-- =================================================================================== -->
<robot name="rrbot" xmlns:xacro="http://www.ros.org/wiki/xacro">
  <!-- Import all Gazebo-customization elements, including Gazebo colors -->
  <!-- ros_control plugin -->
  <gazebo>
    <plugin filename="libgazebo_ros_control.so" name="gazebo_ros_control">
      <robotNamespace>/reactor_arm</robotNamespace>
      <robotSimType>gazebo_ros_control/DefaultRobotHWSim</robotSimType>
    </plugin>
  </gazebo>
  <!-- base_link -->
  <gazebo reference="base_link">
    <material>Gazebo/Orange</material>
  </gazebo>
  <!-- shoulder_link -->
  <gazebo reference="shoulder_link">
    <mu1>0.2</mu1>
    <mu2>0.2</mu2>
    <material>Gazebo/Black</material>
  </gazebo>
  <!-- shoulder_yaw -->
  <gazebo reference="shoulder_yaw">
    <mu1>0.2</mu1>
    <mu2>0.2</mu2>
    <material>Gazebo/Orange</material>
  </gazebo>
  <!-- bicep_link -->
  <gazebo reference="bicep_link">
    <mu1>0.2</mu1>
    <mu2>0.2</mu2>
    <material>Gazebo/Blue</material>
  </gazebo>
  <!-- shoulder_pitch -->
  <gazebo reference="shoulder_pitch">
    <mu1>0.2</mu1>
    <mu2>0.2</mu2>
    <material>Gazebo/Green</material>
  </gazebo>
  <!-- forearm_link -->
  <gazebo reference="forearm_link">
    <mu1>1000.0</mu1>
    <mu2>1000.0</mu2>
    <material>Gazebo/Green</material>
  </gazebo>
  <!-- elbow_pitch -->
  <gazebo reference="elbow_pitch">
    <mu1>1000.0</mu1>
    <mu2>1000.0</mu2>
    <material>Gazebo/Green</material>
  </gazebo>
  <!-- wrist_1 -->
  <gazebo reference="wrist_1">
    <mu1>1000.0</mu1>
    <mu2>1000.0</mu2>
    <material>Gazebo/Green</material>
  </gazebo>
  <!-- wrist_2 -->
  <gazebo reference="wrist_2">
    <mu1>1000.0</mu1>
    <mu2>1000.0</mu2>
    <material>Gazebo/Green</material>
  </gazebo>
  <!-- gripper_link -->
  <gazebo reference="gripper_link">
    <mu1>1000.0</mu1>
    <mu2>1000.0</mu2>
    <material>Gazebo/Green</material>
  </gazebo>
  <!-- camera_link
  <gazebo reference="camera_link">
    <mu1>0.2</mu1>
    <mu2>0.2</mu2>
    <material>Gazebo/Red</material>
  </gazebo>
  -->
  <!-- camera
    <gazebo reference="camera_link">
    <sensor type="camera" name="camera1">
      <update_rate>20.0</update_rate>
      <camera name="head">
        <horizontal_fov>1.3962634</horizontal_fov>
        <image>
          <width>256</width>
          <height>256</height>
          <format>R8G8B8</format>
        </image>
        <clip>
          <near>0.02</near>
          <far>300</far>
        </clip>
        <noise>
          <type>gaussian</type>
          <mean>0.0</mean>
          <stddev>0.007</stddev>
        </noise>
      </camera>
      <plugin name="camera_controller" filename="libgazebo_ros_camera.so">
        <alwaysOn>true</alwaysOn>
        <updateRate>0.0</updateRate>
        <cameraName>rrbot/camera1</cameraName>
        <imageTopicName>image_raw</imageTopicName>
        <cameraInfoTopicName>camera_info</cameraInfoTopicName>
        <frameName>camera_link</frameName>
        <hackBaseline>0.07</hackBaseline>
        <distortionK1>0.0</distortionK1>
        <distortionK2>0.0</distortionK2>
        <distortionK3>0.0</distortionK3>
        <distortionT1>0.0</distortionT1>
        <distortionT2>0.0</distortionT2>
      </plugin>
    </sensor>
  </gazebo>
  -->
  <!-- Import Rviz colors -->
  <material name="black">
    <color rgba="0.0 0.0 0.0 1.0"/>
  </material>
  <material name="blue">
    <color rgba="0.0 0.0 0.8 1.0"/>
  </material>
  <material name="green">
    <color rgba="0.0 0.8 0.0 1.0"/>
  </material>
  <material name="grey">
    <color rgba="0.2 0.2 0.2 1.0"/>
  </material>
  <material name="orange">
    <color rgba="1.0 0.423529411765 0.0392156862745 1.0"/>
  </material>
  <material name="brown">
    <color rgba="0.870588235294 0.811764705882 0.764705882353 1.0"/>
  </material>
  <material name="red">
    <color rgba="0.8 0.0 0.0 1.0"/>
  </material>
  <material name="white">
    <color rgba="1.0 1.0 1.0 1.0"/>
  </material>
  <!-- Used for fixing robot to Gazebo 'base_link' -->
  <link name="world"/>
  <joint name="fixed" type="fixed">
    <parent link="world"/>
    <child link="base_link"/>
  </joint>
  <link name="base_link">
    <visual>
      <origin rpy="0 0 0" xyz="0 0 0"/>
      <geometry>
        <mesh filename="package://reactor_description/meshes/base_link.STL"/>
      </geometry>
      <material name="">
        <color rgba="0.25098 0.25098 0.25098 1"/>
      </material>
    </visual>
    <collision>
      <origin rpy="0 0 0" xyz="0 0 0"/>
      <geometry>
        <mesh filename="package://reactor_description/meshes/base_link_hull.STL"/>
      </geometry>
    </collision>
  </link>
  <link name="shoulder_link">
    <inertial>
      <origin rpy="0 0 0" xyz="5.5296E-07 0.00048339 0.0026355"/>
      <mass value="0.069055"/>
      <inertia ixx="7.786E-05" ixy="4.5909E-11" ixz="-6.4873E-11" iyy="4.1745E-05" iyz="2.8244E-07" izz="0.0001073"/>
    </inertial>
    <visual>
      <origin rpy="0 0 0" xyz="0 0 0"/>
      <geometry>
        <mesh filename="package://reactor_description/meshes/shoulder_link.STL"/>
      </geometry>
      <material name="">
        <color rgba="0.25098 0.25098 0.25098 1"/>
      </material>
    </visual>
    <collision>
      <origin rpy="0 0 0" xyz="0 0 0"/>
      <geometry>
        <mesh filename="package://reactor_description/meshes/shoulder_link_hull.STL"/>
      </geometry>
    </collision>
  </link>
  <joint name="shoulder_yaw" type="revolute">
    <origin rpy="0 0 0" xyz="0 0 0.081"/>
    <parent link="base_link"/>
    <child link="shoulder_link"/>
    <axis xyz="0 0 1"/>
    <limit effort="1.5" lower="-3.141593" upper="3.141593" velocity="6.178465545"/>
  </joint>
  <link name="bicep_link">
    <inertial>
      <origin rpy="0 0 0" xyz="-0.079312 0.00175 0.0073486"/>
      <mass value="0.29331"/>
      <inertia ixx="0.00040741" ixy="-1.1578E-09" ixz="-0.00014106" iyy="0.0010604" iyz="1.1578E-09" izz="0.0012838"/>
    </inertial>
    <visual>
      <origin rpy="0 0 0" xyz="0 0 0"/>
      <geometry>
        <mesh filename="package://reactor_description/meshes/bicep_link.STL"/>
      </geometry>
      <material name="">
        <color rgba="0.32157 0.32157 0.32157 1"/>
      </material>
    </visual>
    <collision>
      <origin rpy="0 0 0" xyz="0 0 0"/>
      <geometry>
        <mesh filename="package://reactor_description/meshes/bicep_link_hull.STL"/>
      </geometry>
    </collision>
  </link>
  <joint name="shoulder_pitch" type="revolute">
    <origin rpy="0 0 0" xyz="0 0 0.0265"/>
    <parent link="shoulder_link"/>
    <child link="bicep_link"/>
    <axis xyz="0 1 0"/>
    <limit effort="3.0" lower="0" upper="3.141593" velocity="6.178465545"/>
  </joint>
  <link name="forearm_link">
    <inertial>
      <origin rpy="0 0 0" xyz="0.0851888339312843 0.00136288621406396 -0.000141576344087929"/>
      <mass value="0.138705662443181"/>
      <inertia ixx="9.73074886909647E-05" ixy="-2.7259894490049E-06" ixz="8.2757647661483E-07" iyy="0.000291190570207828" iyz="-7.99252279784603E-09" izz="0.000367301178753318"/>
    </inertial>
    <visual>
      <origin rpy="0 0 0" xyz="0 0 0"/>
      <geometry>
        <mesh filename="package://reactor_description/meshes/forearm_link.STL"/>
      </geometry>
      <material name="">
        <color rgba="0.250980392156863 0.250980392156863 0.250980392156863 1"/>
      </material>
    </visual>
    <collision>
      <origin rpy="0 0 0" xyz="0 0 0"/>
      <geometry>
        <mesh filename="package://reactor_description/meshes/forearm_link_hull.STL"/>
      </geometry>
    </collision>
  </link>
  <joint name="elbow_pitch" type="revolute">
    <origin rpy="0 0 0" xyz="-0.1445 0 0.0385"/>
    <parent link="bicep_link"/>
    <child link="forearm_link"/>
    <axis xyz="0 -1 0"/>
    <limit effort="3.0" lower="0" upper="3.141593" velocity="6.178465545"/>
  </joint>
  <link name="wrist_1">
    <inertial>
      <origin rpy="0 0 0" xyz="0.0426453655090486 0.0017494960392062 0.00984847105297723"/>
      <mass value="0.0605067986491363"/>
      <inertia ixx="1.78648656995261E-05" ixy="1.11621731933541E-10" ixz="3.58888722407994E-06" iyy="2.8352036542644E-05" iyz="-2.18072661043818E-10" izz="2.38673851634115E-05"/>
    </inertial>
    <visual>
      <origin rpy="0 0 0" xyz="0 0 0"/>
      <geometry>
        <mesh filename="package://reactor_description/meshes/wrist_1.STL"/>
      </geometry>
      <material name="">
        <color rgba="0.250980392156863 0.250980392156863 0.250980392156863 1"/>
      </material>
    </visual>
    <collision>
      <origin rpy="0 0 0" xyz="0 0 0"/>
      <geometry>
        <mesh filename="package://reactor_description/meshes/wrist_1_hull.STL"/>
      </geometry>
    </collision>
  </link>
  <joint name="wrist_pitch" type="revolute">
    <origin rpy="0 0 0" xyz="0.1535 0 0"/>
    <parent link="forearm_link"/>
    <child link="wrist_1"/>
    <axis xyz="0 1 0"/>
    <limit effort="1.5" lower="-1.57079632679" upper="1.57079632679" velocity="6.178465545"/>
  </joint>
  <link name="wrist_2">
    <inertial>
      <origin rpy="0 0 0" xyz="0.022349 -5.4754E-07 0.0089164"/>
      <mass value="0.055706"/>
      <inertia ixx="1.5957E-05" ixy="2.0952E-10" ixz="3.3629E-06" iyy="2.1196E-05" iyz="-2.4643E-10" izz="1.4482E-05"/>
    </inertial>
    <visual>
      <origin rpy="0 0 0" xyz="0 0 0"/>
      <geometry>
        <mesh filename="package://reactor_description/meshes/wrist_2.STL"/>
      </geometry>
      <material name="">
        <color rgba="0.32157 0.32157 0.32157 1"/>
      </material>
    </visual>
    <collision>
      <origin rpy="0 0 0" xyz="0 0 0"/>
      <geometry>
        <mesh filename="package://reactor_description/meshes/wrist_2_hull.STL"/>
      </geometry>
    </collision>
  </link>
  <joint name="wrist_roll" type="revolute">
    <origin rpy="0 0 0" xyz="0.071 0.00175 0"/>
    <parent link="wrist_1"/>
    <child link="wrist_2"/>
    <axis xyz="1 0 0"/>
    <limit effort="1.5" lower="-3.141593" upper="3.141593" velocity="6.178465545"/>
  </joint>
  <link name="gripper_link">
    <inertial>
      <origin rpy="0 0 0" xyz="0.0091884 -7.3309E-13 -3.4513E-05"/>
      <mass value="0.02487"/>
      <inertia ixx="1.5997E-05" ixy="1.6551E-16" ixz="8.3911E-09" iyy="7.3918E-06" iyz="-2.7145E-16" izz="1.5931E-05"/>
    </inertial>
    <visual>
      <origin rpy="0 0 0" xyz="0 0 0"/>
      <geometry>
        <mesh filename="package://reactor_description/meshes/gripper_link.STL"/>
      </geometry>
      <material name="">
        <color rgba="0.25098 0.25098 0.25098 1"/>
      </material>
    </visual>
    <collision>
      <origin rpy="0 0 0" xyz="0 0 0"/>
      <geometry>
        <mesh filename="package://reactor_description/meshes/gripper_link_hull.STL"/>
      </geometry>
    </collision>
  </link>
  <joint name="gripper_joint" type="fixed">
    <origin rpy="0 0 0" xyz="0.04789 0 0"/>
    <parent link="wrist_2"/>
    <child link="gripper_link"/>
    <axis xyz="1 0 0"/>
    <limit effort="1.5" lower="-3.141593" upper="3.141593" velocity="6.178465545"/>
  </joint>
  <transmission name="shoulder_yaw_tran">
    <type>transmission_interface/SimpleTransmission</type>
    <joint name="shoulder_yaw">
      <hardwareInterface>EffortJointInterface</hardwareInterface>
    </joint>
    <actuator name="motor1">
      <hardwareInterface>EffortJointInterface</hardwareInterface>
      <mechanicalReduction>1</mechanicalReduction>
    </actuator>
  </transmission>
  <transmission name="shoulder_pitch_tran">
    <type>transmission_interface/SimpleTransmission</type>
    <joint name="shoulder_pitch">
      <hardwareInterface>EffortJointInterface</hardwareInterface>
    </joint>
    <actuator name="motor2">
      <hardwareInterface>EffortJointInterface</hardwareInterface>
      <mechanicalReduction>1</mechanicalReduction>
    </actuator>
  </transmission>
  <transmission name="elbow_pitch_tran">
    <type>transmission_interface/SimpleTransmission</type>
    <joint name="elbow_pitch">
      <hardwareInterface>EffortJointInterface</hardwareInterface>
    </joint>
    <actuator name="motor3">
      <hardwareInterface>EffortJointInterface</hardwareInterface>
      <mechanicalReduction>1</mechanicalReduction>
    </actuator>
  </transmission>
  <transmission name="wrist_pitch_tran">
    <type>transmission_interface/SimpleTransmission</type>
    <joint name="wrist_pitch">
      <hardwareInterface>EffortJointInterface</hardwareInterface>
    </joint>
    <actuator name="motor4">
      <hardwareInterface>EffortJointInterface</hardwareInterface>
      <mechanicalReduction>1</mechanicalReduction>
    </actuator>
  </transmission>
  <transmission name="wrist_roll_tran">
    <type>transmission_interface/SimpleTransmission</type>
    <joint name="wrist_roll">
      <hardwareInterface>EffortJointInterface</hardwareInterface>
    </joint>
    <actuator name="motor5">
      <hardwareInterface>EffortJointInterface</hardwareInterface>
      <mechanicalReduction>1</mechanicalReduction>
    </actuator>
  </transmission>
  <transmission name="gripper_joint_tran">
    <type>transmission_interface/SimpleTransmission</type>
    <joint name="gripper_joint">
      <hardwareInterface>EffortJointInterface</hardwareInterface>
    </joint>
    <actuator name="motor6">
      <hardwareInterface>EffortJointInterface</hardwareInterface>
      <mechanicalReduction>1</mechanicalReduction>
    </actuator>
  </transmission>
</robot>

